Workbook

Sheet Inicio
A1: Matriz de hardening de firewalls: pfSense · Palo Alto · FortiGate · Check Point
A2: SENATI · Módulo 04 Aseguramiento de los Sistemas · Clase 5 · Material de apoyo
A4: Objetivo | B4: Comparar cómo se verifica el mismo control de seguridad en cuatro plataformas de firewall, y practicar una auditoría con checklist, como en el laboratorio de pfSense.
A5: Metodología (4 frentes) | B5: 1) Plano de gestión contra un benchmark (configuración exportada, sin tocar el equipo). 2) Herramienta nativa del fabricante (BPA, Security Rating, Compliance Blade). 3) Revisión de la base de reglas (any-any, sombreadas, sin uso, sin log, sin dueño). 4) Exposición y parches + vista desde afuera (PSIRT, CISA KEV, escaneo externo, logs en el SIEM).
A6: Hojas | B6: Matriz comparativa: los 33 controles lado a lado. pfSense / Palo Alto / FortiGate / Check Point: checklist por fabricante con cálculo de cumplimiento. Revisión de reglas: qué buscar en la política. Herramientas y benchmarks: qué usar para cada fabricante. Resumen: % de cumplimiento de las cuatro hojas y gráfico.
A7: Cómo llenar | B7: En cada hoja de fabricante, completa solo las celdas amarillas: Estado (lista desplegable) y Evidencia. El resumen de la parte superior y la hoja Resumen se calculan solos. La primera fila de la hoja pfSense trae un ejemplo de cómo registrar la evidencia.
A8: Estados | B8: Cumple · Parcial · No cumple · N.A. (no aplica; justificar en Evidencia) · vacío = pendiente.
A9: Fórmula de cumplimiento | B9: % = (Cumple + 0,5 × Parcial) / (Total − N.A.). Los controles 'Obligatorio' en No cumple se cuentan aparte: son los primeros a corregir.
A10: Advertencia | B10: Las rutas de menú y comandos son de referencia y cambian entre versiones (PAN-OS 10/11, FortiOS 7.0/7.2/7.4/7.6, Check Point R81/R82). Verifícalos en la documentación de la versión auditada. Nunca ejecutes cambios en producción sin ventana aprobada: la auditoría es de solo lectura.
A11: Sobre los benchmarks | B11: Los textos de esta matriz son redacción propia del curso: no reproducen las recomendaciones de los CIS Benchmarks. Para el texto oficial y su numeración, descarga el benchmark en cisecurity.org (gratuito en PDF para uso no comercial).
A12: Fuentes | B12: CIS Benchmarks Palo Alto Networks: https://www.cisecurity.org/benchmark/palo_alto_networks CIS Benchmarks Fortinet: https://www.cisecurity.org/benchmark/fortinet CIS Benchmarks Update octubre 2025 (archivo de Check Point): https://www.cisecurity.org/insights/blog/cis-benchmarks-monthly-update-october-2025 Palo Alto On-Demand BPA: https://docs.paloaltonetworks.com/strata-cloud-manager/aiops/best-practices-in-ngfw/on-demand-bpa-report Fortinet Security Rating (FortiOS 7.4): https://docs.fortinet.com/document/fortigate/7.4.0/best-practices/218775/security-rating Check Point Compliance (R82): https://sc1.checkpoint.com/documents/R82/WebAdminGuides/EN/CP_R82_SecurityManagement_AdminGuide/Content/Topics-SECMG/Compliance.htm CISA KEV: https://www.cisa.gov/known-exploited-vulnerabilities-catalog NIST SP 800-41 Rev. 1 · Lineamiento BB-LIN-SEG-04 Firewall (BurgerBank).
A13: Versión | B13: Octubre 2026 · elaborado para la Clase 5 (Firewalls: del host al perímetro).

Sheet Resumen
A1: Resumen de cumplimiento por plataforma
A2: Se calcula solo a partir de las hojas de cada fabricante.
A4: Plataforma | B4: Equipo / versión | C4: Total | D4: Cumple | E4: Parcial | F4: No cumple | G4: N.A. | H4: Pendientes | I4: % cumplimiento | J4: Obligatorios en No cumple
A5: pfSense | B5: =IF(pfSense!B4="","",pfSense!B4) -> fw-senati · pfSense CE 2.8.1 (ejemplo) | C5: =pfSense!B5 -> 33 | D5: =pfSense!B6 -> 1 | E5: =pfSense!B7 -> 0 | F5: =pfSense!B8 -> 0 | G5: =pfSense!B9 -> 0 | H5: =pfSense!B10 -> 32 | I5: =pfSense!D5 -> 0.03030303 | J5: =pfSense!D8 -> 0
A6: Palo Alto | B6: =IF('Palo Alto'!B4="","",'Palo Alto'!B4) | C6: ='Palo Alto'!B5 -> 33 | D6: ='Palo Alto'!B6 -> 0 | E6: ='Palo Alto'!B7 -> 0 | F6: ='Palo Alto'!B8 -> 0 | G6: ='Palo Alto'!B9 -> 0 | H6: ='Palo Alto'!B10 -> 33 | I6: ='Palo Alto'!D5 -> 0 | J6: ='Palo Alto'!D8 -> 0
A7: FortiGate | B7: =IF(FortiGate!B4="","",FortiGate!B4) | C7: =FortiGate!B5 -> 33 | D7: =FortiGate!B6 -> 0 | E7: =FortiGate!B7 -> 0 | F7: =FortiGate!B8 -> 0 | G7: =FortiGate!B9 -> 0 | H7: =FortiGate!B10 -> 33 | I7: =FortiGate!D5 -> 0 | J7: =FortiGate!D8 -> 0
A8: Check Point | B8: =IF('Check Point'!B4="","",'Check Point'!B4) | C8: ='Check Point'!B5 -> 33 | D8: ='Check Point'!B6 -> 0 | E8: ='Check Point'!B7 -> 0 | F8: ='Check Point'!B8 -> 0 | G8: ='Check Point'!B9 -> 0 | H8: ='Check Point'!B10 -> 33 | I8: ='Check Point'!D5 -> 0 | J8: ='Check Point'!D8 -> 0
A10: Nota: en verde, valores traídos de otras hojas. La única fila con datos de ejemplo es la primera de pfSense.

Sheet Matriz comparativa
A1: Matriz comparativa: el mismo control en cuatro firewalls
A2: Dónde se verifica cada control. Las referencias B2.x / B3.x son secciones del laboratorio de la Clase 5.
A4: ID | B4: Dominio | C4: Control | D4: Riesgo si falla | E4: Nivel | F4: pfSense (laboratorio) | G4: Palo Alto (PAN-OS) | H4: FortiGate (FortiOS) | I4: Check Point (Gaia / SmartConsole)
A5: GES-01 | B5: Gestión | C5: La administración (GUI/SSH/API) solo es accesible desde la red o los hosts de gestión, nunca desde la WAN. | D5: Es la puerta de entrada de los incidentes de 2024–2025 (Ivanti, FortiOS, PAN-OS): interfaz de administración expuesta. | E5: Obligatorio | F5: Regla LAN `GUI solo desde el PC admin` + anti-lockout deshabilitada (B2.3); sin regla de GUI en la WAN (B3.2). | G5: Device › Setup › Interfaces › Management › Permitted IP Addresses; Network › Network Profiles › Interface Mgmt (sin HTTPS/SSH en zonas externas). | H5: System › Administrators › Trusted Hosts; Network › Interfaces › Administrative Access (WAN sin HTTPS/SSH). | I5: Gaia Portal › System Management › Host Access (Allowed Clients); en SmartConsole, stealth rule que proteja gateway y servidor de gestión.
A6: GES-02 | B6: Gestión | C6: Protocolos de administración sin cifrar deshabilitados (HTTP, Telnet). | D6: Credenciales de administrador viajan en claro y pueden ser capturadas. | E6: Obligatorio | F6: System › Advanced › Admin Access: protocolo HTTPS; SSH deshabilitado o solo con llave (B2.5). | G6: Device › Setup › Management › Management Interface Settings: desmarcar HTTP y Telnet; revisar también los Interface Mgmt profiles. | H6: Network › Interfaces › Administrative Access: sin HTTP ni TELNET en ninguna interfaz. | I6: Gaia Portal › System Management › Network Access: Telnet deshabilitado.
A7: GES-03 | B7: Gestión | C7: Gestión cifrada con TLS 1.2 o superior y certificado emitido por una CA de confianza (no el autofirmado de fábrica). | D7: Un certificado autofirmado acostumbra a los administradores a aceptar avisos, facilitando un ataque de intermediario. | E7: Recomendado | F7: System › Cert Manager + Admin Access › SSL/TLS Certificate (B2.2). | G7: Device › Certificate Management › SSL/TLS Service Profile (versión mínima TLSv1.2) asignado en Device › Setup › Management. | H7: System › Settings / CLI: cifrado fuerte y versiones TLS de la GUI; certificado de administración propio. | I7: Gaia Portal: reemplazar el certificado autofirmado del portal web; SmartConsole/gestión con certificados internos (ICA).
A8: GES-04 | B8: Gestión | C8: Cierre de sesión por inactividad de la administración (≤ 15 minutos). | D8: Una sesión abierta en un equipo desatendido permite cambios sin autenticarse. | E8: Obligatorio | F8: System › User Manager › Settings › Session timeout = 15 (B2.4). | G8: Device › Setup › Management › Authentication Settings › Idle Timeout. | H8: System › Settings › Idle timeout. | I8: Gaia Portal › User Management › Session; también el timeout de SmartConsole.
A9: GES-05 | B9: Gestión | C9: Banner de aviso legal antes del inicio de sesión. | D9: Sin aviso de uso autorizado se debilita la base legal ante un acceso indebido. | E9: Recomendado | F9: Sin opción nativa en la GUI: documentar como N.A. o excepción. | G9: Device › Setup › Management › General Settings › Login Banner. | H9: System › Replacement Messages + pre-login-banner habilitado. | I9: Gaia Portal › System Management › Messages (banner).
A10: AUT-01 | B10: Autenticación | C10: Cuentas nominales para el día a día; la cuenta de fábrica (admin) solo como emergencia y con clave cambiada y custodiada. | D10: Cuentas compartidas impiden saber quién hizo cada cambio; la clave de fábrica es la primera que prueba un atacante. | E10: Obligatorio | F10: System › User Manager (B2.1). | G10: Device › Administrators: una cuenta por persona; admin con clave cambiada. | H10: System › Administrators. | I10: Gaia Portal › User Management › Users; SmartConsole › Manage & Settings › Permissions & Administrators.
A11: AUT-02 | B11: Autenticación | C11: Política de contraseñas: longitud mínima, complejidad y no reutilización según la política de la empresa. | D11: Claves débiles se adivinan por fuerza bruta o diccionario. | E11: Obligatorio | F11: Sin política de complejidad nativa: aplicar por procedimiento o con autenticación centralizada. | G11: Device › Setup › Management › Minimum Password Complexity. | H11: System › Settings › Password Policy. | I11: Gaia Portal › User Management › Password Policy.
A12: AUT-03 | B12: Autenticación | C12: Bloqueo temporal tras varios intentos fallidos de inicio de sesión. | D12: Sin bloqueo, la fuerza bruta contra la gestión no tiene límite. | E12: Obligatorio | F12: System › Advanced › Admin Access › Login Protection (B2.4). | G12: Device › Authentication Profile › Failed Attempts / Lockout Time (perfil usado por los administradores). | H12: System › Settings: umbral y duración de bloqueo de administradores. | I12: Gaia Portal › User Management › Password Policy (bloqueo por intentos fallidos).
A13: AUT-04 | B13: Autenticación | C13: MFA y autenticación centralizada (RADIUS, TACACS+ o SAML) para administradores. | D13: Una clave robada basta para tomar el firewall. | E13: Recomendado | F13: System › User Manager › Authentication Servers (RADIUS/LDAP). Fuera del alcance del laboratorio. | G13: Device › Authentication Profile (SAML/RADIUS con MFA) asignado a los administradores. | H13: System › Administrators: Two-factor (FortiToken) o servidor remoto RADIUS/TACACS+. | I13: SmartConsole › Permissions & Administrators: método de autenticación RADIUS/TACACS+; Gaia Portal › User Management › Authentication Servers.
A14: AUT-05 | B14: Autenticación | C14: Mínimo privilegio: perfiles de solo lectura para quien no necesita cambiar la configuración. | D14: Todos con superusuario multiplica el impacto de una cuenta comprometida. | E14: Recomendado | F14: System › User Manager › Groups / privilegios por página. | G14: Device › Admin Roles. | H14: System › Admin Profiles. | I14: SmartConsole › Permission Profiles; Gaia roles (RBA).
A15: SRV-01 | B15: Servicios | C15: Solo los servicios necesarios activos en el equipo (sin UPnP, servicios de prueba, portales sin uso). | D15: Cada servicio extra es superficie de ataque y fuente de vulnerabilidades. | E15: Obligatorio | F15: Services › UPnP deshabilitado; paquetes no usados desinstalados (B2.6, B2.8). | G15: Revisar Interface Mgmt profiles, GlobalProtect portal, servicios de User-ID expuestos. | H15: Revisar allowaccess por interfaz y funciones habilitadas (System › Feature Visibility). | I15: Revisar blades activos y servicios de Gaia.
... A37: RES-02 | B37: Respaldo y continuidad | C37: Alta disponibilidad configurada y probada, con la configuración sincronizada (si aplica). | D37: Un único equipo es un punto único de falla. | E37: Recomendado | F37: System › High Availability (CARP); fuera del laboratorio. | G37: Device › High Availability. | H37: System › HA. | I37: ClusterXL.

Sheet pfSense
A1: Checklist de hardening · pfSense
A2: Plataforma de referencia: pfSense CE 2.8.x. Completa las celdas amarillas (Estado y Evidencia).
A4: Equipo / versión auditada | B4: fw-senati · pfSense CE 2.8.1 (ejemplo) | D4: % de cumplimiento
A5: Total de controles | B5: =COUNTA($A$12:$A$44) -> 33 | D5: =IFERROR((B6+0.5*B7)/(B5-B9),0) -> 0.03030303
A6: Cumple | B6: =COUNTIF($H$12:$H$44,"Cumple") -> 1
A7: Parcial | B7: =COUNTIF($H$12:$H$44,"Parcial") -> 0 | D7: Obligatorios en No cumple
A8: No cumple | B8: =COUNTIF($H$12:$H$44,"No cumple") -> 0 | D8: =COUNTIFS($G$12:$G$44,"Obligatorio",$H$12:$H$44,"No cumple") -> 0
A9: N.A. | B9: =COUNTIF($H$12:$H$44,"N.A.") -> 0
A10: Pendientes (sin estado) | B10: =B5-B6-B7-B8-B9 -> 32
A11: ID | B11: Dominio | C11: Control | D11: Dónde verificar (GUI) | E11: CLI / evidencia sugerida | F11: Resultado esperado | G11: Nivel | H11: Estado | I11: Evidencia / comentario
A12: GES-01 | B12: Gestión | C12: La administración (GUI/SSH/API) solo es accesible desde la red o los hosts de gestión, nunca desde la WAN. | D12: Regla LAN `GUI solo desde el PC admin` + anti-lockout deshabilitada (B2.3); sin regla de GUI en la WAN (B3.2). | E12: Kali: curl -sk https://IP_WAN/ → timeout | F12: Desde la WAN la gestión no responde (filtered). Solo hosts de gestión autorizados. | G12: Obligatorio | H12: Cumple | I12: EJEMPLO: captura de la regla LAN 'GUI solo desde el PC admin' + Kali: curl a https://IP_WAN_PF/ da timeout (batería P1: 443 filtered).
A13: GES-02 | B13: Gestión | C13: Protocolos de administración sin cifrar deshabilitados (HTTP, Telnet). | D13: System › Advanced › Admin Access: protocolo HTTPS; SSH deshabilitado o solo con llave (B2.5). | E13: Auditor: ADM-* (auditar-pfsense.py) | F13: Solo HTTPS y SSH (o solo HTTPS) habilitados para gestión. | G13: Obligatorio
A14: GES-03 | B14: Gestión | C14: Gestión cifrada con TLS 1.2 o superior y certificado emitido por una CA de confianza (no el autofirmado de fábrica). | D14: System › Cert Manager + Admin Access › SSL/TLS Certificate (B2.2). | E14: Navegador: ver el certificado de la GUI | F14: TLS ≥ 1.2, cifrados fuertes y certificado de CA interna. | G14: Recomendado
A15: GES-04 | B15: Gestión | C15: Cierre de sesión por inactividad de la administración (≤ 15 minutos). | D15: System › User Manager › Settings › Session timeout = 15 (B2.4). | F15: Timeout de 10–15 minutos o menos. | G15: Obligatorio
A16: GES-05 | B16: Gestión | C16: Banner de aviso legal antes del inicio de sesión. | D16: Sin opción nativa en la GUI: documentar como N.A. o excepción. | F16: Banner visible en GUI y SSH. | G16: Recomendado
A17: AUT-01 | B17: Autenticación | C17: Cuentas nominales para el día a día; la cuenta de fábrica (admin) solo como emergencia y con clave cambiada y custodiada. | D17: System › User Manager (B2.1). | E17: Auditor: ADM-01 / ADM-02 | F17: Una cuenta por persona; admin con clave larga en bóveda. | G17: Obligatorio
A18: AUT-02 | B18: Autenticación | C18: Política de contraseñas: longitud mínima, complejidad y no reutilización según la política de la empresa. | D18: Sin política de complejidad nativa: aplicar por procedimiento o con autenticación centralizada. | F18: Política configurada en el equipo o en el servidor central de autenticación. | G18: Obligatorio
A19: AUT-03 | B19: Autenticación | C19: Bloqueo temporal tras varios intentos fallidos de inicio de sesión. | D19: System › Advanced › Admin Access › Login Protection (B2.4). | F19: Bloqueo tras 3–10 intentos durante un tiempo definido. | G19: Obligatorio
A20: AUT-04 | B20: Autenticación | C20: MFA y autenticación centralizada (RADIUS, TACACS+ o SAML) para administradores. | D20: System › User Manager › Authentication Servers (RADIUS/LDAP). Fuera del alcance del laboratorio. | F20: Administradores autentican contra IdP/RADIUS con segundo factor. | G20: Recomendado
A21: AUT-05 | B21: Autenticación | C21: Mínimo privilegio: perfiles de solo lectura para quien no necesita cambiar la configuración. | D21: System › User Manager › Groups / privilegios por página. | F21: Roles diferenciados (lectura, operador, superusuario). | G21: Recomendado
A22: SRV-01 | B22: Servicios | C22: Solo los servicios necesarios activos en el equipo (sin UPnP, servicios de prueba, portales sin uso). | D22: Services › UPnP deshabilitado; paquetes no usados desinstalados (B2.6, B2.8). | E22: Auditor: SRV-* | F22: Inventario de servicios justificado; lo demás deshabilitado. | G22: Obligatorio
A23: SRV-02 | B23: Servicios | C23: SNMP deshabilitado o en v3 (sin comunidad 'public'/'private'), restringido a la IP del sistema de monitoreo. | D23: Services › SNMP deshabilitado (B2.6). | E23: Desde la DMZ: nmap -sU -p161 --script snmp-info | F23: SNMPv3 con autenticación y cifrado, o SNMP apagado. | G23: Obligatorio
A24: SRV-03 | B24: Servicios | C24: Hora sincronizada con servidores NTP confiables. | D24: System › General Setup › Time servers (B2.8). | F24: Al menos 2 servidores NTP; estado sincronizado. | G24: Obligatorio
A25: SRV-04 | B25: Servicios | C25: DNS del equipo hacia servidores confiables; el resolvedor no responde en la WAN. | D25: Services › DNS Resolver › Network Interfaces: LAN, DMZ, Localhost (B2.6). | E25: Kali: nmap -sU -p53 IP_WAN | F25: Resolvedor solo en interfaces internas. | G25: Recomendado
A26: LOG-01 | B26: Logs y monitoreo | C26: Logs enviados a un servidor central o SIEM, fuera del equipo. | D26: Status › System Logs › Settings › Remote Logging (B2.7). | E26: Ubuntu: sudo tail -f /var/log/pfsense.log | F26: Syslog/colector central recibiendo eventos de sistema y tráfico. | G26: Obligatorio
A27: LOG-02 | B27: Logs y monitoreo | C27: Se registra el tráfico denegado por la regla final y el permitido en reglas críticas. | D27: Status › System Logs › Settings › Log packets matched from the default block rules (B2.7); log en reglas Block (B3). | F27: Regla de limpieza con log; reglas de servicios publicados con log. | G27: Obligatorio
A28: LOG-03 | B28: Logs y monitoreo | C28: Auditoría de cambios de configuración y de accesos de administradores. | D28: Status › System Logs › General; Diagnostics › Backup & Restore (historial de configuraciones). | F28: Registro de quién cambió qué y cuándo, enviado al SIEM. | G28: Obligatorio
A29: ACT-01 | B29: Actualizaciones | C29: Sistema operativo del equipo en versión soportada y parcheada; seguimiento del PSIRT del fabricante y del catálogo KEV de CISA. | D29: System › Update (B2.8). | F29: Versión soportada sin vulnerabilidades críticas pendientes; evidencia del último parche. | G29: Obligatorio
A30: ACT-02 | B30: Actualizaciones | C30: Firmas y contenido de seguridad (IPS, antivirus, aplicaciones, URL) actualizados automáticamente. | D30: Suricata › Updates (B5, opcional). | F30: Actualización programada y última descarga reciente. | G30: Obligatorio
A31: REG-01 | B31: Reglas | C31: Denegación por defecto: regla final explícita que bloquea y registra todo lo no permitido (cleanup rule). | D31: Regla Block final con log en LAN y DMZ (B3.3, B3.4). | F31: Última regla: any → any → deny con log. | G31: Obligatorio
A32: REG-02 | B32: Reglas | C32: Stealth rule: nadie inicia conexiones hacia el propio firewall salvo la gestión autorizada. | D32: Reglas DMZ/LAN sin acceso a 'This Firewall' salvo DNS/NTP y GUI desde ADMIN_PC (B2.3, B3.4). | E32: Desde la DMZ: curl -sk https://172.16.20.1/ → timeout | F32: Tráfico hacia el firewall bloqueado salvo desde gestión. | G32: Obligatorio
A33: REG-03 | B33: Reglas | C33: Sin reglas 'any-any' ni permisos más amplios de lo necesario (origen, destino y servicio específicos). | D33: Se elimina la regla 'permitir todo' de la DMZ y la Default allow LAN (B3.3, B3.4). | F33: Ninguna regla con origen, destino y servicio 'any' a la vez. | G33: Obligatorio
A34: REG-04 | B34: Reglas | C34: Reglas sin uso (sin coincidencias en 90 días o más) revisadas y eliminadas. | D34: Firewall › Rules: columna de estados por regla; Diagnostics › pfInfo. | F34: Informe de hit count revisado en cada ciclo. | G34: Recomendado
A35: REG-05 | B35: Reglas | C35: Cada regla con descripción, dueño o ticket y fecha de revisión. | D35: Campo Description en cada regla (B3). | E35: Auditor: REG-* | F35: 100 % de reglas con descripción y responsable. | G35: Recomendado
A36: REG-06 | B36: Reglas | C36: Filtrado de salida: servidores y usuarios solo hacia los destinos y puertos necesarios. | D36: Reglas LAN y DMZ de salida (B3.3, B3.4); prueba P5 de la batería. | E36: pruebas-firewall.sh → P5 | F36: Salida limitada a DNS, actualizaciones y servicios justificados. | G36: Obligatorio
A37: REG-07 | B37: Reglas | C37: Segmentación: la DMZ no inicia conexiones hacia redes internas ni hacia la red de gestión. | D37: Regla DMZ → RED_PRIVADA bloqueada con log (B3.4). | E37: Ubuntu (DMZ): nmap 192.168.56.0/24 → filtered | F37: DMZ → redes internas bloqueado y registrado. | G37: Obligatorio
A38: REG-08 | B38: Reglas | C38: Anti-spoofing: se rechazan en la WAN direcciones privadas, bogons o que no corresponden a la interfaz. | D38: Interfaces › WAN › Block private networks / bogon networks (EXC en el lab, B4.4). | F38: Protección anti-spoofing activa en interfaces externas. | G38: Obligatorio
A39: REG-09 | B39: Reglas | C39: Perfiles de prevención de amenazas (IPS, antivirus, filtrado URL) aplicados a las reglas que permiten tráfico de internet. | D39: Suricata en la WAN (B5, opcional). | F39: Toda regla allow hacia/desde internet con perfil de seguridad. | G39: Recomendado
A40: REG-10 | B40: Reglas | C40: Protección contra inundaciones y DoS en interfaces externas. | D40: Opciones avanzadas por regla (límite de conexiones por origen; reto en la referencia). | F40: Umbrales de protección definidos en la zona externa. | G40: Recomendado
A41: VPN-01 | B41: VPN | C41: Acceso remoto VPN con MFA; portales sin uso deshabilitados y versión parcheada. | D41: OpenVPN/IPsec con autenticación fuerte (fuera del laboratorio). | F41: MFA obligatorio; solo los portales necesarios publicados. | G41: Obligatorio
...

Sheet Palo Alto
A1: Checklist de hardening · Palo Alto
A2: Plataforma de referencia: PAN-OS 10.x / 11.x. Completa las celdas amarillas (Estado y Evidencia).
A4: Equipo / versión auditada | D4: % de cumplimiento
A5: Total de controles | B5: =COUNTA($A$12:$A$44) -> 33 | D5: =IFERROR((B6+0.5*B7)/(B5-B9),0) -> 0
A6: Cumple | B6: =COUNTIF($H$12:$H$44,"Cumple") -> 0
A7: Parcial | B7: =COUNTIF($H$12:$H$44,"Parcial") -> 0 | D7: Obligatorios en No cumple
A8: No cumple | B8: =COUNTIF($H$12:$H$44,"No cumple") -> 0 | D8: =COUNTIFS($G$12:$G$44,"Obligatorio",$H$12:$H$44,"No cumple") -> 0
A9: N.A. | B9: =COUNTIF($H$12:$H$44,"N.A.") -> 0
A10: Pendientes (sin estado) | B10: =B5-B6-B7-B8-B9 -> 33
A11: ID | B11: Dominio | C11: Control | D11: Dónde verificar (GUI) | E11: CLI / evidencia sugerida | F11: Resultado esperado | G11: Nivel | H11: Estado | I11: Evidencia / comentario
A12: GES-01 | B12: Gestión | C12: La administración (GUI/SSH/API) solo es accesible desde la red o los hosts de gestión, nunca desde la WAN. | D12: Device › Setup › Interfaces › Management › Permitted IP Addresses; Network › Network Profiles › Interface Mgmt (sin HTTPS/SSH en zonas externas). | E12: set cli config-output-format set show config running | match permitted-ip | F12: Desde la WAN la gestión no responde (filtered). Solo hosts de gestión autorizados. | G12: Obligatorio
A13: GES-02 | B13: Gestión | C13: Protocolos de administración sin cifrar deshabilitados (HTTP, Telnet). | D13: Device › Setup › Management › Management Interface Settings: desmarcar HTTP y Telnet; revisar también los Interface Mgmt profiles. | E13: show config running | match disable- | F13: Solo HTTPS y SSH (o solo HTTPS) habilitados para gestión. | G13: Obligatorio
A14: GES-03 | B14: Gestión | C14: Gestión cifrada con TLS 1.2 o superior y certificado emitido por una CA de confianza (no el autofirmado de fábrica). | D14: Device › Certificate Management › SSL/TLS Service Profile (versión mínima TLSv1.2) asignado en Device › Setup › Management. | E14: show config running | match ssl-tls-service-profile | F14: TLS ≥ 1.2, cifrados fuertes y certificado de CA interna. | G14: Recomendado
A15: GES-04 | B15: Gestión | C15: Cierre de sesión por inactividad de la administración (≤ 15 minutos). | D15: Device › Setup › Management › Authentication Settings › Idle Timeout. | E15: show config running | match idle-timeout | F15: Timeout de 10–15 minutos o menos. | G15: Obligatorio
A16: GES-05 | B16: Gestión | C16: Banner de aviso legal antes del inicio de sesión. | D16: Device › Setup › Management › General Settings › Login Banner. | E16: show config running | match login-banner | F16: Banner visible en GUI y SSH. | G16: Recomendado
A17: AUT-01 | B17: Autenticación | C17: Cuentas nominales para el día a día; la cuenta de fábrica (admin) solo como emergencia y con clave cambiada y custodiada. | D17: Device › Administrators: una cuenta por persona; admin con clave cambiada. | E17: show admins all | F17: Una cuenta por persona; admin con clave larga en bóveda. | G17: Obligatorio
A18: AUT-02 | B18: Autenticación | C18: Política de contraseñas: longitud mínima, complejidad y no reutilización según la política de la empresa. | D18: Device › Setup › Management › Minimum Password Complexity. | E18: show config running | match password-complexity | F18: Política configurada en el equipo o en el servidor central de autenticación. | G18: Obligatorio
A19: AUT-03 | B19: Autenticación | C19: Bloqueo temporal tras varios intentos fallidos de inicio de sesión. | D19: Device › Authentication Profile › Failed Attempts / Lockout Time (perfil usado por los administradores). | E19: show config running | match failed-attempts | F19: Bloqueo tras 3–10 intentos durante un tiempo definido. | G19: Obligatorio
A20: AUT-04 | B20: Autenticación | C20: MFA y autenticación centralizada (RADIUS, TACACS+ o SAML) para administradores. | D20: Device › Authentication Profile (SAML/RADIUS con MFA) asignado a los administradores. | E20: show config running | match authentication-profile | F20: Administradores autentican contra IdP/RADIUS con segundo factor. | G20: Recomendado
A21: AUT-05 | B21: Autenticación | C21: Mínimo privilegio: perfiles de solo lectura para quien no necesita cambiar la configuración. | D21: Device › Admin Roles. | E21: show config running | match role | F21: Roles diferenciados (lectura, operador, superusuario). | G21: Recomendado
A22: SRV-01 | B22: Servicios | C22: Solo los servicios necesarios activos en el equipo (sin UPnP, servicios de prueba, portales sin uso). | D22: Revisar Interface Mgmt profiles, GlobalProtect portal, servicios de User-ID expuestos. | E22: show config running | match interface-management-profile | F22: Inventario de servicios justificado; lo demás deshabilitado. | G22: Obligatorio
A23: SRV-02 | B23: Servicios | C23: SNMP deshabilitado o en v3 (sin comunidad 'public'/'private'), restringido a la IP del sistema de monitoreo. | D23: Device › Setup › Operations › SNMP Setup (versión v3). | E23: show config running | match snmp | F23: SNMPv3 con autenticación y cifrado, o SNMP apagado. | G23: Obligatorio
... A26: LOG-01 | B26: Logs y monitoreo | C26: Logs enviados a un servidor central o SIEM, fuera del equipo. | D26: Device › Server Profiles › Syslog + Objects › Log Forwarding (o Strata Logging Service / Panorama). | E26: show config running | match syslog | F26: Syslog/colector central recibiendo eventos de sistema y tráfico. | G26: Obligatorio
A27: LOG-02 | B27: Logs y monitoreo | C27: Se registra el tráfico denegado por la regla final y el permitido en reglas críticas. | D27: En cada regla: Actions › Log at Session End; regla final deny con log (las reglas por defecto no registran salvo que se cambie). | F27: Regla de limpieza con log; reglas de servicios publicados con log. | G27: Obligatorio
A28: LOG-03 | B28: Logs y monitoreo | C28: Auditoría de cambios de configuración y de accesos de administradores. | D28: Monitor › Logs › Configuration y System. | E28: show log config | F28: Registro de quién cambió qué y cuándo, enviado al SIEM. | G28: Obligatorio
A29: ACT-01 | B29: Actualizaciones | C29: Sistema operativo del equipo en versión soportada y parcheada; seguimiento del PSIRT del fabricante y del catálogo KEV de CISA. | D29: Device › Software; comparar con security.paloaltonetworks.com. | E29: show system info | F29: Versión soportada sin vulnerabilidades críticas pendientes; evidencia del último parche. | G29: Obligatorio
A30: ACT-02 | B30: Actualizaciones | C30: Firmas y contenido de seguridad (IPS, antivirus, aplicaciones, URL) actualizados automáticamente. | D30: Device › Dynamic Updates (programación de Apps/Threats, AV, WildFire). | E30: show config running | match update-schedule | F30: Actualización programada y última descarga reciente. | G30: Obligatorio
A31: REG-01 | B31: Reglas | C31: Denegación por defecto: regla final explícita que bloquea y registra todo lo no permitido (cleanup rule). | D31: Policies › Security: regla final deny con log antes de las reglas por defecto. | F31: Última regla: any → any → deny con log. | G31: Obligatorio
A32: REG-02 | B32: Reglas | C32: Stealth rule: nadie inicia conexiones hacia el propio firewall salvo la gestión autorizada. | D32: Interface Mgmt profiles mínimos + reglas hacia las IP del firewall. | F32: Tráfico hacia el firewall bloqueado salvo desde gestión. | G32: Obligatorio
A33: REG-03 | B33: Reglas | C33: Sin reglas 'any-any' ni permisos más amplios de lo necesario (origen, destino y servicio específicos). | D33: Policies › Security: filtrar reglas con any en origen, destino y aplicación/servicio; usar App-ID. | F33: Ninguna regla con origen, destino y servicio 'any' a la vez. | G33: Obligatorio
A34: REG-04 | B34: Reglas | C34: Reglas sin uso (sin coincidencias en 90 días o más) revisadas y eliminadas. | D34: Policies › Security › Policy Optimizer / Rule Usage. | E34: show running rule-use rule-base security type unused vsys vsys1 | F34: Informe de hit count revisado en cada ciclo. | G34: Recomendado
A35: REG-05 | B35: Reglas | C35: Cada regla con descripción, dueño o ticket y fecha de revisión. | D35: Campos Description y Tags en cada regla. | F35: 100 % de reglas con descripción y responsable. | G35: Recomendado
A36: REG-06 | B36: Reglas | C36: Filtrado de salida: servidores y usuarios solo hacia los destinos y puertos necesarios. | D36: Reglas de salida por App-ID y URL filtering. | F36: Salida limitada a DNS, actualizaciones y servicios justificados. | G36: Obligatorio
A37: REG-07 | B37: Reglas | C37: Segmentación: la DMZ no inicia conexiones hacia redes internas ni hacia la red de gestión. | D37: Zonas separadas y reglas entre zonas (intrazone/interzone). | F37: DMZ → redes internas bloqueado y registrado. | G37: Obligatorio
A38: REG-08 | B38: Reglas | C38: Anti-spoofing: se rechazan en la WAN direcciones privadas, bogons o que no corresponden a la interfaz. | D38: Network › Network Profiles › Zone Protection › Packet Based Attack Protection (Spoofed IP). | E38: show config running | match zone-protection-profile | F38: Protección anti-spoofing activa en interfaces externas. | G38: Obligatorio
A39: REG-09 | B39: Reglas | C39: Perfiles de prevención de amenazas (IPS, antivirus, filtrado URL) aplicados a las reglas que permiten tráfico de internet. | D39: Security Profile Group en las reglas allow. | E39: show config running | match profile-setting | F39: Toda regla allow hacia/desde internet con perfil de seguridad. | G39: Recomendado
A40: REG-10 | B40: Reglas | C40: Protección contra inundaciones y DoS en interfaces externas. | D40: Zone Protection Profile (Flood Protection) en la zona externa. | F40: Umbrales de protección definidos en la zona externa. | G40: Recomendado
A41: VPN-01 | B41: VPN | C41: Acceso remoto VPN con MFA; portales sin uso deshabilitados y versión parcheada. | D41: Network › GlobalProtect: Authentication Profile con MFA. | F41: MFA obligatorio; solo los portales necesarios publicados. | G41: Obligatorio
A42: VPN-02 | B42: VPN | C42: Criptografía VPN fuerte (IKEv2, AES-GCM, grupos DH modernos; sin 3DES, MD5 ni SHA-1). | D42: Network › Network Profiles › IKE Crypto / IPSec Crypto. | F42: Propuestas IKE/IPsec solo con algoritmos fuertes. | G42: Recomendado
A43: RES-01 | B43: Respaldo y continuidad | C43: Respaldo cifrado de la configuración, guardado fuera del equipo, con restauración probada. | D43: Device › Setup › Operations › Export named configuration snapshot; exportación programada desde Panorama. | F43: Respaldo periódico cifrado + evidencia de prueba de restauración. | G43: Obligatorio
...

Sheet FortiGate
A1: Checklist de hardening · FortiGate
A2: Plataforma de referencia: FortiOS 7.0 – 7.6. Completa las celdas amarillas (Estado y Evidencia).
A4: Equipo / versión auditada | D4: % de cumplimiento
A5: Total de controles | B5: =COUNTA($A$12:$A$44) -> 33 | D5: =IFERROR((B6+0.5*B7)/(B5-B9),0) -> 0
A6: Cumple | B6: =COUNTIF($H$12:$H$44,"Cumple") -> 0
A7: Parcial | B7: =COUNTIF($H$12:$H$44,"Parcial") -> 0 | D7: Obligatorios en No cumple
A8: No cumple | B8: =COUNTIF($H$12:$H$44,"No cumple") -> 0 | D8: =COUNTIFS($G$12:$G$44,"Obligatorio",$H$12:$H$44,"No cumple") -> 0
A9: N.A. | B9: =COUNTIF($H$12:$H$44,"N.A.") -> 0
A10: Pendientes (sin estado) | B10: =B5-B6-B7-B8-B9 -> 33
A11: ID | B11: Dominio | C11: Control | D11: Dónde verificar (GUI) | E11: CLI / evidencia sugerida | F11: Resultado esperado | G11: Nivel | H11: Estado | I11: Evidencia / comentario
A12: GES-01 | B12: Gestión | C12: La administración (GUI/SSH/API) solo es accesible desde la red o los hosts de gestión, nunca desde la WAN. | D12: System › Administrators › Trusted Hosts; Network › Interfaces › Administrative Access (WAN sin HTTPS/SSH). | E12: show system admin (trusthost) show system interface (allowaccess) | F12: Desde la WAN la gestión no responde (filtered). Solo hosts de gestión autorizados. | G12: Obligatorio
A13: GES-02 | B13: Gestión | C13: Protocolos de administración sin cifrar deshabilitados (HTTP, Telnet). | D13: Network › Interfaces › Administrative Access: sin HTTP ni TELNET en ninguna interfaz. | E13: show system interface (allowaccess) | F13: Solo HTTPS y SSH (o solo HTTPS) habilitados para gestión. | G13: Obligatorio
A14: GES-03 | B14: Gestión | C14: Gestión cifrada con TLS 1.2 o superior y certificado emitido por una CA de confianza (no el autofirmado de fábrica). | D14: System › Settings / CLI: cifrado fuerte y versiones TLS de la GUI; certificado de administración propio. | E14: show full-configuration system global | grep -i -e strong-crypto -e admin-https-ssl -e admin-server-cert | F14: TLS ≥ 1.2, cifrados fuertes y certificado de CA interna. | G14: Recomendado
A15: GES-04 | B15: Gestión | C15: Cierre de sesión por inactividad de la administración (≤ 15 minutos). | D15: System › Settings › Idle timeout. | E15: show full-configuration system global | grep admintimeout | F15: Timeout de 10–15 minutos o menos. | G15: Obligatorio
A16: GES-05 | B16: Gestión | C16: Banner de aviso legal antes del inicio de sesión. | D16: System › Replacement Messages + pre-login-banner habilitado. | E16: show full-configuration system global | grep login-banner | F16: Banner visible en GUI y SSH. | G16: Recomendado
A17: AUT-01 | B17: Autenticación | C17: Cuentas nominales para el día a día; la cuenta de fábrica (admin) solo como emergencia y con clave cambiada y custodiada. | D17: System › Administrators. | E17: show system admin | F17: Una cuenta por persona; admin con clave larga en bóveda. | G17: Obligatorio
A18: AUT-02 | B18: Autenticación | C18: Política de contraseñas: longitud mínima, complejidad y no reutilización según la política de la empresa. | D18: System › Settings › Password Policy. | E18: show system password-policy | F18: Política configurada en el equipo o en el servidor central de autenticación. | G18: Obligatorio
A19: AUT-03 | B19: Autenticación | C19: Bloqueo temporal tras varios intentos fallidos de inicio de sesión. | D19: System › Settings: umbral y duración de bloqueo de administradores. | E19: show full-configuration system global | grep admin-lockout | F19: Bloqueo tras 3–10 intentos durante un tiempo definido. | G19: Obligatorio
A20: AUT-04 | B20: Autenticación | C20: MFA y autenticación centralizada (RADIUS, TACACS+ o SAML) para administradores. | D20: System › Administrators: Two-factor (FortiToken) o servidor remoto RADIUS/TACACS+. | E20: show system admin (two-factor) | F20: Administradores autentican contra IdP/RADIUS con segundo factor. | G20: Recomendado
A21: AUT-05 | B21: Autenticación | C21: Mínimo privilegio: perfiles de solo lectura para quien no necesita cambiar la configuración. | D21: System › Admin Profiles. | E21: show system accprofile | F21: Roles diferenciados (lectura, operador, superusuario). | G21: Recomendado
A22: SRV-01 | B22: Servicios | C22: Solo los servicios necesarios activos en el equipo (sin UPnP, servicios de prueba, portales sin uso). | D22: Revisar allowaccess por interfaz y funciones habilitadas (System › Feature Visibility). | E22: show system interface | F22: Inventario de servicios justificado; lo demás deshabilitado. | G22: Obligatorio
A23: SRV-02 | B23: Servicios | C23: SNMP deshabilitado o en v3 (sin comunidad 'public'/'private'), restringido a la IP del sistema de monitoreo. | D23: System › SNMP: sin comunidades v1/v2c por defecto; usuarios v3 con hosts restringidos. | E23: show system snmp community show system snmp user | F23: SNMPv3 con autenticación y cifrado, o SNMP apagado. | G23: Obligatorio
... A27: LOG-02 | B27: Logs y monitoreo | C27: Se registra el tráfico denegado por la regla final y el permitido en reglas críticas. | D27: En cada política: Log Allowed Traffic; registro de tráfico denegado implícito habilitado. | E27: show firewall policy (logtraffic) | F27: Regla de limpieza con log; reglas de servicios publicados con log. | G27: Obligatorio
A28: LOG-03 | B28: Logs y monitoreo | C28: Auditoría de cambios de configuración y de accesos de administradores. | D28: Log & Report › Events › System Events. | F28: Registro de quién cambió qué y cuándo, enviado al SIEM. | G28: Obligatorio
A29: ACT-01 | B29: Actualizaciones | C29: Sistema operativo del equipo en versión soportada y parcheada; seguimiento del PSIRT del fabricante y del catálogo KEV de CISA. | D29: System › Firmware & Registration; comparar con fortiguard.com/psirt. | E29: get system status | F29: Versión soportada sin vulnerabilidades críticas pendientes; evidencia del último parche. | G29: Obligatorio
A30: ACT-02 | B30: Actualizaciones | C30: Firmas y contenido de seguridad (IPS, antivirus, aplicaciones, URL) actualizados automáticamente. | D30: System › FortiGuard (actualizaciones programadas). | E30: diagnose autoupdate versions | F30: Actualización programada y última descarga reciente. | G30: Obligatorio
A31: REG-01 | B31: Reglas | C31: Denegación por defecto: regla final explícita que bloquea y registra todo lo no permitido (cleanup rule). | D31: Policy & Objects › Firewall Policy: denegación implícita con log habilitado. | F31: Última regla: any → any → deny con log. | G31: Obligatorio
A32: REG-02 | B32: Reglas | C32: Stealth rule: nadie inicia conexiones hacia el propio firewall salvo la gestión autorizada. | D32: Policy & Objects › Local In Policy. | E32: show firewall local-in-policy | F32: Tráfico hacia el firewall bloqueado salvo desde gestión. | G32: Obligatorio
A33: REG-03 | B33: Reglas | C33: Sin reglas 'any-any' ni permisos más amplios de lo necesario (origen, destino y servicio específicos). | D33: Policy & Objects › Firewall Policy: buscar srcaddr all / dstaddr all / service ALL. | E33: show firewall policy | F33: Ninguna regla con origen, destino y servicio 'any' a la vez. | G33: Obligatorio
A34: REG-04 | B34: Reglas | C34: Reglas sin uso (sin coincidencias en 90 días o más) revisadas y eliminadas. | D34: Policy & Objects › Firewall Policy: columnas Hit Count y Last Used. | F34: Informe de hit count revisado en cada ciclo. | G34: Recomendado
A35: REG-05 | B35: Reglas | C35: Cada regla con descripción, dueño o ticket y fecha de revisión. | D35: Campo Comments en cada política. | F35: 100 % de reglas con descripción y responsable. | G35: Recomendado
A36: REG-06 | B36: Reglas | C36: Filtrado de salida: servidores y usuarios solo hacia los destinos y puertos necesarios. | D36: Políticas de salida con servicios específicos y perfiles de seguridad. | F36: Salida limitada a DNS, actualizaciones y servicios justificados. | G36: Obligatorio
A37: REG-07 | B37: Reglas | C37: Segmentación: la DMZ no inicia conexiones hacia redes internas ni hacia la red de gestión. | D37: Políticas entre interfaces/zonas. | F37: DMZ → redes internas bloqueado y registrado. | G37: Obligatorio
A38: REG-08 | B38: Reglas | C38: Anti-spoofing: se rechazan en la WAN direcciones privadas, bogons o que no corresponden a la interfaz. | D38: Verificación de ruta inversa (RPF) activa por defecto: confirmar que asymroute esté deshabilitado. | E38: show full-configuration system settings | grep asymroute | F38: Protección anti-spoofing activa en interfaces externas. | G38: Obligatorio
A39: REG-09 | B39: Reglas | C39: Perfiles de prevención de amenazas (IPS, antivirus, filtrado URL) aplicados a las reglas que permiten tráfico de internet. | D39: Security Profiles (IPS/AV/Web Filter) en las políticas. | E39: show firewall policy | F39: Toda regla allow hacia/desde internet con perfil de seguridad. | G39: Recomendado
A40: REG-10 | B40: Reglas | C40: Protección contra inundaciones y DoS en interfaces externas. | D40: Policy & Objects › DoS Policy en la interfaz WAN. | E40: show firewall DoS-policy | F40: Umbrales de protección definidos en la zona externa. | G40: Recomendado
A41: VPN-01 | B41: VPN | C41: Acceso remoto VPN con MFA; portales sin uso deshabilitados y versión parcheada. | D41: VPN › IPsec / SSL-VPN: usuarios con autenticación de dos factores. | E41: show vpn ssl settings | F41: MFA obligatorio; solo los portales necesarios publicados. | G41: Obligatorio
A42: VPN-02 | B42: VPN | C42: Criptografía VPN fuerte (IKEv2, AES-GCM, grupos DH modernos; sin 3DES, MD5 ni SHA-1). | D42: VPN › IPsec Tunnels: propuestas de Phase 1/2. | E42: show vpn ipsec phase1-interface | F42: Propuestas IKE/IPsec solo con algoritmos fuertes. | G42: Recomendado
A43: RES-01 | B43: Respaldo y continuidad | C43: Respaldo cifrado de la configuración, guardado fuera del equipo, con restauración probada. | D43: System › Configuration › Backup (con cifrado). | F43: Respaldo periódico cifrado + evidencia de prueba de restauración. | G43: Obligatorio
A44: RES-02 | B44: Respaldo y continuidad | C44: Alta disponibilidad configurada y probada, con la configuración sincronizada (si aplica). | D44: System › HA. | E44: get system ha status | F44: Prueba de conmutación documentada. | G44: Recomendado

Sheet Check Point
A1: Checklist de hardening · Check Point
A2: Plataforma de referencia: Gaia R81 / R82. Completa las celdas amarillas (Estado y Evidencia).
A4: Equipo / versión auditada | D4: % de cumplimiento
A5: Total de controles | B5: =COUNTA($A$12:$A$44) -> 33 | D5: =IFERROR((B6+0.5*B7)/(B5-B9),0) -> 0
A6: Cumple | B6: =COUNTIF($H$12:$H$44,"Cumple") -> 0
A7: Parcial | B7: =COUNTIF($H$12:$H$44,"Parcial") -> 0 | D7: Obligatorios en No cumple
A8: No cumple | B8: =COUNTIF($H$12:$H$44,"No cumple") -> 0 | D8: =COUNTIFS($G$12:$G$44,"Obligatorio",$H$12:$H$44,"No cumple") -> 0
A9: N.A. | B9: =COUNTIF($H$12:$H$44,"N.A.") -> 0
A10: Pendientes (sin estado) | B10: =B5-B6-B7-B8-B9 -> 33
A11: ID | B11: Dominio | C11: Control | D11: Dónde verificar (GUI) | E11: CLI / evidencia sugerida | F11: Resultado esperado | G11: Nivel | H11: Estado | I11: Evidencia / comentario
A12: GES-01 | B12: Gestión | C12: La administración (GUI/SSH/API) solo es accesible desde la red o los hosts de gestión, nunca desde la WAN. | D12: Gaia Portal › System Management › Host Access (Allowed Clients); en SmartConsole, stealth rule que proteja gateway y servidor de gestión. | E12: clish: show allowed-client all | F12: Desde la WAN la gestión no responde (filtered). Solo hosts de gestión autorizados. | G12: Obligatorio
A13: GES-02 | B13: Gestión | C13: Protocolos de administración sin cifrar deshabilitados (HTTP, Telnet). | D13: Gaia Portal › System Management › Network Access: Telnet deshabilitado. | E13: clish: show net-access telnet | F13: Solo HTTPS y SSH (o solo HTTPS) habilitados para gestión. | G13: Obligatorio
A14: GES-03 | B14: Gestión | C14: Gestión cifrada con TLS 1.2 o superior y certificado emitido por una CA de confianza (no el autofirmado de fábrica). | D14: Gaia Portal: reemplazar el certificado autofirmado del portal web; SmartConsole/gestión con certificados internos (ICA). | E14: Navegador: ver el certificado del Gaia Portal | F14: TLS ≥ 1.2, cifrados fuertes y certificado de CA interna. | G14: Recomendado
A15: GES-04 | B15: Gestión | C15: Cierre de sesión por inactividad de la administración (≤ 15 minutos). | D15: Gaia Portal › User Management › Session; también el timeout de SmartConsole. | E15: clish: show inactivity-timeout | F15: Timeout de 10–15 minutos o menos. | G15: Obligatorio
A16: GES-05 | B16: Gestión | C16: Banner de aviso legal antes del inicio de sesión. | D16: Gaia Portal › System Management › Messages (banner). | E16: clish: show configuration message | F16: Banner visible en GUI y SSH. | G16: Recomendado
A17: AUT-01 | B17: Autenticación | C17: Cuentas nominales para el día a día; la cuenta de fábrica (admin) solo como emergencia y con clave cambiada y custodiada. | D17: Gaia Portal › User Management › Users; SmartConsole › Manage & Settings › Permissions & Administrators. | E17: clish: show users | F17: Una cuenta por persona; admin con clave larga en bóveda. | G17: Obligatorio
A18: AUT-02 | B18: Autenticación | C18: Política de contraseñas: longitud mínima, complejidad y no reutilización según la política de la empresa. | D18: Gaia Portal › User Management › Password Policy. | E18: clish: show password-controls all | F18: Política configurada en el equipo o en el servidor central de autenticación. | G18: Obligatorio
A19: AUT-03 | B19: Autenticación | C19: Bloqueo temporal tras varios intentos fallidos de inicio de sesión. | D19: Gaia Portal › User Management › Password Policy (bloqueo por intentos fallidos). | E19: clish: show password-controls all | F19: Bloqueo tras 3–10 intentos durante un tiempo definido. | G19: Obligatorio
A20: AUT-04 | B20: Autenticación | C20: MFA y autenticación centralizada (RADIUS, TACACS+ o SAML) para administradores. | D20: SmartConsole › Permissions & Administrators: método de autenticación RADIUS/TACACS+; Gaia Portal › User Management › Authentication Servers. | F20: Administradores autentican contra IdP/RADIUS con segundo factor. | G20: Recomendado
A21: AUT-05 | B21: Autenticación | C21: Mínimo privilegio: perfiles de solo lectura para quien no necesita cambiar la configuración. | D21: SmartConsole › Permission Profiles; Gaia roles (RBA). | E21: clish: show rba all | F21: Roles diferenciados (lectura, operador, superusuario). | G21: Recomendado
A22: SRV-01 | B22: Servicios | C22: Solo los servicios necesarios activos en el equipo (sin UPnP, servicios de prueba, portales sin uso). | D22: Revisar blades activos y servicios de Gaia. | E22: cpstat fw clish: show configuration | F22: Inventario de servicios justificado; lo demás deshabilitado. | G22: Obligatorio
A23: SRV-02 | B23: Servicios | C23: SNMP deshabilitado o en v3 (sin comunidad 'public'/'private'), restringido a la IP del sistema de monitoreo. | D23: Gaia Portal › System Management › SNMP (v3-only). | E23: clish: show configuration snmp | F23: SNMPv3 con autenticación y cifrado, o SNMP apagado. | G23: Obligatorio
A24: SRV-03 | B24: Servicios | C24: Hora sincronizada con servidores NTP confiables. | D24: Gaia Portal › System Management › Time. | E24: clish: show ntp servers | F24: Al menos 2 servidores NTP; estado sincronizado. | G24: Obligatorio
A25: SRV-04 | B25: Servicios | C25: DNS del equipo hacia servidores confiables; el resolvedor no responde en la WAN. | D25: Gaia Portal › Network Management › Hosts and DNS. | E25: clish: show dns primary | F25: Resolvedor solo en interfaces internas. | G25: Recomendado
A26: LOG-01 | B26: Logs y monitoreo | C26: Logs enviados a un servidor central o SIEM, fuera del equipo. | D26: Logs al Log Server/SmartEvent; Gaia Portal › System Management › System Logging (syslog remoto). | E26: clish: show configuration syslog | F26: Syslog/colector central recibiendo eventos de sistema y tráfico. | G26: Obligatorio
A27: LOG-02 | B27: Logs y monitoreo | C27: Se registra el tráfico denegado por la regla final y el permitido en reglas críticas. | D27: SmartConsole: columna Track = Log en la cleanup rule y reglas críticas. | F27: Regla de limpieza con log; reglas de servicios publicados con log. | G27: Obligatorio
A28: LOG-03 | B28: Logs y monitoreo | C28: Auditoría de cambios de configuración y de accesos de administradores. | D28: Logs & Monitor › Audit Logs. | F28: Registro de quién cambió qué y cuándo, enviado al SIEM. | G28: Obligatorio
A29: ACT-01 | B29: Actualizaciones | C29: Sistema operativo del equipo en versión soportada y parcheada; seguimiento del PSIRT del fabricante y del catálogo KEV de CISA. | D29: Gaia Portal › CPUSE (Jumbo Hotfix); comparar con los avisos de Check Point. | E29: clish: show version all expert: cpinfo -y all | F29: Versión soportada sin vulnerabilidades críticas pendientes; evidencia del último parche. | G29: Obligatorio
A30: ACT-02 | B30: Actualizaciones | C30: Firmas y contenido de seguridad (IPS, antivirus, aplicaciones, URL) actualizados automáticamente. | D30: SmartConsole › Security Policies › Threat Prevention › Updates. | F30: Actualización programada y última descarga reciente. | G30: Obligatorio
A31: REG-01 | B31: Reglas | C31: Denegación por defecto: regla final explícita que bloquea y registra todo lo no permitido (cleanup rule). | D31: SmartConsole: cleanup rule Any/Any/Drop con Log al final de la capa. | F31: Última regla: any → any → deny con log. | G31: Obligatorio
A32: REG-02 | B32: Reglas | C32: Stealth rule: nadie inicia conexiones hacia el propio firewall salvo la gestión autorizada. | D32: SmartConsole: stealth rule (gateway + servidor de gestión) en las primeras posiciones. | F32: Tráfico hacia el firewall bloqueado salvo desde gestión. | G32: Obligatorio
A33: REG-03 | B33: Reglas | C33: Sin reglas 'any-any' ni permisos más amplios de lo necesario (origen, destino y servicio específicos). | D33: SmartConsole: buscar reglas Any/Any/Any Accept. | F33: Ninguna regla con origen, destino y servicio 'any' a la vez. | G33: Obligatorio
A34: REG-04 | B34: Reglas | C34: Reglas sin uso (sin coincidencias en 90 días o más) revisadas y eliminadas. | D34: SmartConsole: columna Hits del rulebase. | F34: Informe de hit count revisado en cada ciclo. | G34: Recomendado
A35: REG-05 | B35: Reglas | C35: Cada regla con descripción, dueño o ticket y fecha de revisión. | D35: Columna Comments / Name y metadatos de la regla. | F35: 100 % de reglas con descripción y responsable. | G35: Recomendado
A36: REG-06 | B36: Reglas | C36: Filtrado de salida: servidores y usuarios solo hacia los destinos y puertos necesarios. | D36: Reglas de salida con Application & URL Filtering. | F36: Salida limitada a DNS, actualizaciones y servicios justificados. | G36: Obligatorio
A37: REG-07 | B37: Reglas | C37: Segmentación: la DMZ no inicia conexiones hacia redes internas ni hacia la red de gestión. | D37: Reglas entre redes/zonas en la capa de acceso. | F37: DMZ → redes internas bloqueado y registrado. | G37: Obligatorio
A38: REG-08 | B38: Reglas | C38: Anti-spoofing: se rechazan en la WAN direcciones privadas, bogons o que no corresponden a la interfaz. | D38: Gateway › Network Management › Topología de cada interfaz › Anti-Spoofing. | F38: Protección anti-spoofing activa en interfaces externas. | G38: Obligatorio
A39: REG-09 | B39: Reglas | C39: Perfiles de prevención de amenazas (IPS, antivirus, filtrado URL) aplicados a las reglas que permiten tráfico de internet. | D39: Threat Prevention policy y blades IPS/Anti-Bot/Anti-Virus activos. | E39: cpstat fw | F39: Toda regla allow hacia/desde internet con perfil de seguridad. | G39: Recomendado
A40: REG-10 | B40: Reglas | C40: Protección contra inundaciones y DoS en interfaces externas. | D40: IPS protecciones de red y Rate Limiting. | E40: expert: fw samp get | F40: Umbrales de protección definidos en la zona externa. | G40: Recomendado
A41: VPN-01 | B41: VPN | C41: Acceso remoto VPN con MFA; portales sin uso deshabilitados y versión parcheada. | D41: Remote Access / Mobile Access con MFA. | F41: MFA obligatorio; solo los portales necesarios publicados. | G41: Obligatorio
...

Sheet Revisión de reglas
A1: Revisión de la base de reglas: lo que el benchmark no ve
A2: Aplica igual a los cuatro fabricantes. Es donde más hallazgos aparecen en una auditoría real.
A4: ID | B4: Qué buscar | C4: Por qué importa | D4: Cómo encontrarlo | E4: Hallazgos (cantidad) | F4: Comentario
A5: RR-01 | B5: Reglas 'any-any' o con servicio 'any' hacia redes internas | C5: Anulan la política: todo lo demás sobra. | D5: Filtrar reglas con any en origen, destino y servicio.
A6: RR-02 | B6: Reglas sombreadas (nunca coinciden porque otra más arriba las cubre) | C6: Dan una falsa sensación de control. | D6: Herramienta de análisis (Policy Optimizer, Nipper, AlgoSec, Tufin) o revisión manual del orden.
A7: RR-03 | B7: Reglas sin uso en 90 días o más | C7: Accesos olvidados que nadie recuerda por qué existen. | D7: Hit count / Last used; confirmar con el dueño antes de borrar.
A8: RR-04 | B8: Reglas sin log | C8: No hay evidencia ni detección. | D8: Revisar la columna de log/track en reglas allow críticas y en la cleanup rule.
A9: RR-05 | B9: Reglas sin descripción, dueño o ticket | C9: Nadie se atreve a eliminarlas. | D9: Exigir descripción + responsable + fecha de revisión.
A10: RR-06 | B10: Servicios peligrosos permitidos desde/hacia internet (SMB, RDP, Telnet, bases de datos) | C10: Vectores clásicos de ransomware e intrusión. | D10: Buscar puertos 445, 3389, 23, 1433, 3306, 5432, 6379 en reglas con origen internet.
A11: RR-07 | B11: NAT/publicaciones con origen 'any' que podrían restringirse | C11: Exposición innecesaria del servicio publicado. | D11: Restringir el origen (ej. KALI_EXTERNO en el lab) o publicar detrás de VPN.
A12: RR-08 | B12: Objetos y grupos duplicados o sin uso | C12: Confunden y esconden errores. | D12: Limpieza de objetos no referenciados.
A13: RR-09 | B13: Reglas temporales vencidas | C13: Lo 'temporal' se vuelve permanente. | D13: Fecha de expiración en la regla o en el ticket; revisión trimestral.
A14: RR-10 | B14: Reglas allow hacia internet sin perfil de seguridad | C14: Tráfico permitido sin inspección. | D14: Verificar IPS/AV/URL en cada regla allow.
D15: Total de hallazgos | E15: =SUM(E5:E14) -> 0

Sheet Herramientas y benchmarks
A1: Herramientas y benchmarks por fabricante
A2: Estado verificado en octubre de 2026. Revisa la licencia del cliente: varias funciones nativas son de pago.
A4: Fabricante | B4: Benchmark CIS disponible | C4: Herramienta nativa | D4: Notas y licencia | E4: Auditoría externa / multifabricante | F4: Qué pedir al cliente | G4: Fuente
A5: pfSense | B5: CIS pfSense Firewall (listado en cisecurity.org). | C5: No tiene evaluador nativo: en el curso se usa auditar-pfsense.py sobre el config.xml. | D5: Exportar config.xml sin cifrar solo para auditar y borrarlo con shred después (B1.1, B4.1). | E5: Revisión manual del config.xml. | F5: config.xml (Diagnostics › Backup & Restore). | G5: https://learn.cisecurity.org/Benchmarks
A6: Palo Alto | B6: CIS Palo Alto Firewall 11 (v1.2.0) y Firewall 10 (v1.2.0 / FINAL v1.3.0). | C6: Best Practice Assessment (BPA) en Strata Cloud Manager / AIOps for NGFW, subiendo un Tech Support File. | D6: Desde el 17/07/2023 el BPA ya no se ejecuta desde el Customer Support Portal. En foros de 2026 reportan que el BPA ad-hoc requiere licencia AIOps Premium o SCM Pro, o la API: confirmarlo con la licencia del cliente. | E6: Nessus (archivos .audit CIS de Palo Alto), Nipper, AlgoSec, Tufin, FireMon. | F6: Running config XML o Tech Support File; exportación de Panorama si existe. | G6: https://www.cisecurity.org/benchmark/palo_alto_networks https://docs.paloaltonetworks.com/strata-cloud-manager/aiops/best-practices-in-ngfw/on-demand-bpa-report
A7: FortiGate | B7: CIS FortiGate 7.0.x (v1.4.0) y FortiGate 7.4.x (v1.0.1). | C7: Security Rating (Security Fabric › Security Rating). | D7: Incluye pruebas sin licencia; considera NIST, PCI DSS, GDPR y CIS. La vista agrupada por CIS (desde 7.4.1) requiere licencia Attack Surface Security Rating. | E7: Nessus (CIS FortiGate L1/L2 + Tenable FortiOS Best Practices), Nipper, AlgoSec, Tufin, FireMon. | F7: Respaldo completo de configuración; salida de get system status. | G7: https://www.cisecurity.org/benchmark/fortinet https://docs.fortinet.com/document/fortigate/7.4.0/new-features/794602
A8: Check Point | B8: CIS Check Point Firewall v1.1.0, archivado por CIS desde el 10/10/2025 por falta de expertos: usar como referencia histórica. | C8: Compliance Software Blade (SmartConsole › Compliance) con biblioteca de buenas prácticas de Check Point. | D8: Monitorea gateways, blades, políticas y configuración de forma continua. Una revisión independiente (CheckMates) encontró límites: no validaba que la stealth rule incluya el servidor de gestión ni manejaba inline layers. Complementar con revisión manual. | E8: Nipper, AlgoSec, Tufin, FireMon. | F8: Configuración de Gaia (clish show configuration) y exportación del policy package desde el servidor de gestión. | G8: https://www.cisecurity.org/insights/blog/cis-benchmarks-monthly-update-october-2025 https://sc1.checkpoint.com/documents/R82/WebAdminGuides/EN/CP_R82_SecurityManagement_AdminGuide/Content/Topics-SECMG/Compliance.htm
A9: Todos | B9: — | C9: — | D9: Antes de auditar configuraciones: versión vs. avisos del fabricante (PSIRT) y catálogo KEV de CISA. En equipos perimetrales pesa más que cualquier configuración. | E9: Escaneo externo (nmap, como la batería de Kali) y verificación de logs en el SIEM. | F9: Versión exacta y fecha del último parche. | G9: https://www.cisa.gov/known-exploited-vulnerabilities-catalog
